Workbook
Name Felber: #REF!

Sheet 2.2 Kandidaten
A1: Gemeinde | B1: Sitze | C1: CVP | E1: FDP | G1: SP/Grüne/Gew. | I1: SVP | K1: Total
C2: Total Kand. | D2: davon Frauen | E2: Total Kand. | F2: davon Frauen | G2: Total Kand. | H2: davon Frauen | I2: Total Kand. | J2: davon Frauen | K2: Total Kand. | L2: davon Frauen
A4: Altdorf | B4: 15 | C4: 8 | D4: 3 | E4: 8 | F4: 1 | G4: 9 | H4: 4 | I4: 8 | J4: 1 | K4: =SUM(I4,G4,E4,C4) -> 33 | L4: =SUM(J4,H4,F4,D4) -> 9
A5: Bürglen | B5: 7 | C5: 5 | D5: 3 | E5: 5 | F5: 1 | G5: 4 | H5: 2 | I5: 4 | J5: 0 | K5: =SUM(I5,G5,E5,C5) -> 18 | L5: =SUM(J5,H5,F5,D5) -> 6
A6: Erstfeld | B6: 6 | C6: 4 | D6: 1 | E6: 4 | F6: 0 | G6: 3 | H6: 2 | I6: 3 | J6: 0 | K6: =SUM(I6,G6,E6,C6) -> 14 | L6: =SUM(J6,H6,F6,D6) -> 3
A7: Schattdorf | B7: 9 | C7: 5 | D7: 1 | E7: 5 | F7: 1 | G7: 5 | H7: 2 | I7: 5 | J7: 0 | K7: =SUM(I7,G7,E7,C7) -> 20 | L7: =SUM(J7,H7,F7,D7) -> 4
A9: Total | B9: =SUM(B4:B7) -> 37 | C9: =SUM(C4:C8) -> 22 | D9: =SUM(D4:D8) -> 8 | E9: =SUM(E4:E8) -> 22 | F9: =SUM(F4:F8) -> 3 | G9: =SUM(G4:G8) -> 21 | H9: =SUM(H4:H8) -> 10 | I9: =SUM(I4:I8) -> 20 | J9: =SUM(J4:J8) -> 1 | K9: =SUM(K4:K8) -> 85 | L9: =SUM(J9,H9,F9,D9) -> 22
D10: =D9/C9 -> 0.36363636 | F10: =F9/E9 -> 0.13636364 | H10: =H9/G9 -> 0.47619048 | J10: =J9/I9 -> 0.05 | L10: =L9/K9 -> 0.25882353
A13: 2020

Sheet Kandidaten Jahre 1992 - 2020
A1: Vergleich Wahlen Anzahl Kandidierende in den Proporzgemeinden
A2: Jahr | B2: Gden. | C2: Sitze | D2: CVP | F2: FDP | H2: SP/Grüne/Gew. | J2: SVP | L2: Total Kand.
D3: Total Kand. | E3: davon Frauen | F3: Total Kand. | G3: davon Frauen | H3: Total Kand. | I3: davon Frauen | J3: Total Kand. | K3: davon Frauen | L3: Total Kand. | M3: davon Frauen | N3: in %
A5: 1992 | B5: 7 | C5: 47 | D5: 55 | E5: 10 | F5: 42 | G5: 9 | H5: 38 | I5: 12 | L5: =SUM(J5,H5,F5,D5) -> 135 | M5: =SUM(K5,I5,G5,E5) -> 31 | N5: =M5/L5 -> 0.22962963
A6: 1996 | B6: 8 | C6: 50 | D6: 54 | E6: 11 | F6: 25 | G6: 5 | H6: 36 | I6: 17 | J6: 1 | K6: 0 | L6: =SUM(J6,H6,F6,D6) -> 116 | M6: =SUM(K6,I6,G6,E6) -> 33 | N6: =M6/L6 -> 0.28448276
A7: 2000 | B7: 8 | C7: 50 | D7: 46 | E7: 11 | F7: 35 | G7: 8 | H7: 25 | I7: 10 | J7: 16 | K7: 0 | L7: =SUM(J7,H7,F7,D7) -> 122 | M7: =SUM(K7,I7,G7,E7) -> 29 | N7: =M7/L7 -> 0.23770492
A8: 2004 | B8: 8 | C8: 50 | D8: 54 | E8: 10 | F8: 31 | G8: 3 | H8: 23 | I8: 11 | J8: 20 | K8: 5 | L8: =SUM(J8,H8,F8,D8) -> 128 | M8: =SUM(K8,I8,G8,E8) -> 29 | N8: =M8/L8 -> 0.2265625
A9: 2008 | B9: 8 | C9: 50 | D9: 40 | E9: 13 | F9: 27 | G9: 5 | H9: 25 | I9: 9 | J9: 28 | K9: 2 | L9: =SUM(J9,H9,F9,D9) -> 120 | M9: =SUM(K9,I9,G9,E9) -> 29 | N9: =M9/L9 -> 0.24166667
A10: 2012 | B10: 8 | C10: 50 | D10: 37 | E10: 11 | F10: 26 | G10: 8 | H10: 26 | I10: 9 | J10: 32 | K10: 4 | L10: =SUM(D10,F10,H10,J10) -> 121 | M10: =SUM(K10,I10,G10,E10) -> 32 | N10: =M10/L10 -> 0.26446281
A11: 2016 | B11: 8 | C11: 50 | D11: 38 | E11: 13 | F11: 31 | G11: 6 | H11: 25 | I11: 9 | J11: 38 | K11: 3 | L11: 132 | M11: 31 | N11: =M11/L11 -> 0.23484848
A12: 2020 | B12: 4 | C12: 37 | D12: 22 | E12: 8 | F12: 22 | G12: 3 | H12: 21 | I12: 10 | J12: 20 | K12: 1 | L12: =SUM(J12,H12,F12,D12) -> 85 | M12: =SUM(K12,I12,G12,E12) -> 22 | N12: =M12/L12 -> 0.25882353

Sheet 3 Stimmbeteiligung
A1: Stimmbeteiligung | D1: ="= Ausfüllen" -> = Ausfüllen
A2: Gemeinde | B2: Stimmber. | C2: Stimmbet. | D2: 2020 | E2: 2016 | F2: 2012 | G2: 2008 | H2: 2004
D3: in % | E3: in % | F3: in % | G3: in % | H3: in %
A5: Altdorf | B5: 6636 | C5: 2827 | D5: =C5/B5*100 -> 42.600964 | E5: 58.939487 | F5: 49.155458 | G5: 39.536024 | H5: 47.4
A6: Bürglen | B6: 3073 | C6: 1343 | D6: =C6/B6*100 -> 43.703222 | E6: 62.211828 | F6: 50.272665 | G6: 42.695473 | H6: 46.2
A7: Erstfeld | B7: 2545 | C7: 1124 | D7: =C7/B7*100 -> 44.165029 | E7: 61.310699 | F7: 46.156788 | G7: 42.186326 | H7: 50.6
A8: Schattdorf | B8: 3989 | C8: 1629 | D8: =C8/B8*100 -> 40.837303 | E8: 61.137566 | F8: 45.707408 | G8: 38.192905 | H8: 46
A10: Alle Proporz-gemeinden | B10: =SUM(B5:B8) -> 16243 | C10: =SUM(C5:C8) -> 6923 | D10: =C10/B10*100 -> 42.621437
A12: Andermatt | B12: 933 | C12: 471 | D12: =C12/B12*100 -> 50.482315 | E12: 78.223185 | F12: 49.094782 | G12: 49.733759 | H12: 50
A13: Attinghausen | D13: Stille Wahl | E13: 59.982788 | F13: 57.91776 | G13: 44.107143 | H13: 54.7
A14: Bauen | D14: Gdevers. | E14: Gdevers. | F14: Gdevers. | G14: Gdevers. | H14: Gdevers.
A15: Flüelen | B15: 1411 | C15: 710 | D15: =C15/B15*100 -> 50.318923 | E15: 67.067138 | F15: 47.466096 | G15: 39.380531 | H15: 44
A16: Göschenen | B16: 309 | C16: 185 | D16: =C16/B16*100 -> 59.87055 | E16: 68.253968 | F16: 52 | G16: 46.857143 | H16: 48.4
A17: Gurtnellen | B17: 412 | C17: 200 | D17: =C17/B17*100 -> 48.543689 | E17: 73.820755 | F17: 58.444444 | G17: 24.691358 | H17: 58.1
A18: Hospental | B18: 142 | C18: 68 | D18: =C18/B18*100 -> 47.887324 | E18: 60.416667 | F18: 53.424658 | G18: 54.375 | H18: 77
A19: Isenthal | D19: Gdevers. | E19: Gdevers. | F19: Gdevers. | G19: Gdevers. | H19: Gdevers.
A20: Realp | B20: 114 | C20: 76 | D20: =C20/B20*100 -> 66.666667 | E20: 78.4 | F20: 56.8 | G20: 50 | H20: 59
A21: Seedorf | B21: 1306 | C21: 700 | D21: =C21/B21*100 -> 53.598775 | E21: Stille Wahl | F21: 48.412698 | G21: 35.289324 | H21: 56.9
A22: Seelisberg | D22: Stille Wahl | E22: 52.12766 | F22: 42.826087 | G22: 24.463519 | H22: 35.7
A23: Silenen | D23: Stille Wahl | E23: 63.912201 | F23: Stille Wahl | G23: 36.311423 | H23: 50
A24: Sisikon | B24: 234 | C24: 74 | D24: =C24/B24*100 -> 31.623932 | E24: 56.078431 | F24: 47.252747 | G24: 32.835821 | H24: 40
A25: Spiringen | B25: 664 | C25: 316 | D25: =C25/B25*100 -> 47.590361 | E25: 51.593323 | F25: 63.955343 | G25: 55.130168 | H25: 37.4
A26: Unterschächen | B26: 543 | C26: 280 | D26: =C26/B26*100 -> 51.565378 | E26: 64.684015 | F26: 75.384615 | G26: 37.524178 | H26: Gdevers.
A27: Wassen | D27: Stille Wahl | E27: 76.109215 | F27: 49.546828 | G27: 43.026706 | H27: 60.4
A29: Alle Majorz-gemeinden | B29: =SUM(B12:B27) -> 6068 | C29: =SUM(C12:C27) -> 3080 | D29: =C29/(B29)*100 -> 50.758075
A31: Total | B31: =B29+B10 -> 22311 | C31: =C29+C10 -> 10003 | D31: =C31/(B31)*100 -> 44.834387
A35: Stimmbeteiligung Regierungsratswahlen
A37: Gemeinde | B37: Stimmber. | C37: Stimmbet. LR | D37: in % | E37: Stimmbet. RR | F37: in %
A40: Altdorf | B40: 6975 | C40: 3612 | D40: =C40/B40*100 -> 51.784946 | E40: 3234 | F40: =E40/B40*100 -> 46.365591
A41: Bürglen | B41: 2936 | C41: 1633 | D41: =C41/B41*100 -> 55.619891 | E41: 1717 | F41: =E41/B41*100 -> 58.480926
A42: Erstfeld | B42: 2455 | C42: 1334 | D42: =C42/B42*100 -> 54.338086 | E42: 1361 | F42: =E42/B42*100 -> 55.437882
A43: Schattdorf | B43: 3948 | C43: 2071 | D43: =C43/B43*100 -> 52.45694 | E43: 2164 | F43: =E43/B43*100 -> 54.812563
A45: Alle Proporz-gemeinden | B45: =SUM(B40:B43) -> 16314 | C45: =SUM(C40:C43) -> 8650 | D45: =C45/B45*100 -> 53.021944 | E45: =SUM(E40:E43) -> 8476 | F45: =E45/B45*100 -> 51.955376
A47: Andermatt | B47: 951 | C47: 621 | D47: 65.3 | E47: 562 | F47: =E47/B47*100 -> 59.095689
A48: Attinghausen | B48: 1309 | C48: 734 | D48: 56.1 | E48: 760 | F48: =E48/B48*100 -> 58.059587
A49: Flüelen | B49: 1422 | C49: 869 | D49: 61.1 | E49: 846 | F49: =E49/B49*100 -> 59.493671
A50: Göschenen | B50: 290 | C50: 198 | D50: 68.3 | E50: 180 | F50: =E50/B50*100 -> 62.068966
A51: Gurtnellen | B51: 394 | C51: 206 | D51: 52.3 | E51: 220 | F51: =E51/B51*100 -> 55.837563
A52: Hospental | B52: 124 | C52: 63 | D52: 50.8 | E52: 62 | F52: =E52/B52*100 -> 50
A53: Isenthal | B53: 354 | C53: Gdevers. | D53: Gdevers. | E53: 189 | F53: =E53/B53*100 -> 53.389831
...

Sheet 6 Gültige WZ
A1: Gültige Wahlzettel mit Listenbezeichnung 2020
A2: Gemeinde | B2: Total | C2: CVP | G2: FDP | K2: Gemeinde | L2: Total | M2: SP/Grüne | Q2: SVP
C3: unverändert | E3: verändert | G3: unverändert | I3: verändert | M3: unverändert | O3: verändert | Q3: unverändert | S3: verändert | Y3: leer/ungültig | Z3: kontrolle | AA3: ohne
C4: abs. | D4: % | E4: abs. | F4: % | G4: abs. | H4: % | I4: abs. | J4: % | M4: abs. | N4: % | O4: abs. | P4: % | Q4: abs. | R4: % | S4: abs. | T4: %
A6: Altdorf | B6: =C6+E6+G6+I6+M6+O6+Q6+S6 -> 2353 | C6: 251 | D6: =C6/(E6+C6) -> 0.39280125 | E6: 388 | F6: =E6/(C6+E6) -> 0.60719875 | G6: 217 | H6: =G6/(I6+G6) -> 0.42465753 | I6: 294 | J6: =I6/(G6+I6) -> 0.57534247 | K6: =A6 -> Altdorf | L6: =B6 -> 2353 | M6: 457 | N6: =M6/(O6+M6) -> 0.62774725 | O6: 271 | P6: =O6/(M6+O6) -> 0.37225275 | Q6: 325 | R6: =Q6/(S6+Q6) -> 0.68421053 | S6: 150 | T6: =S6/(Q6+S6) -> 0.31578947 | Y6: =-B6+Z6-AA6 -> 0 | Z6: 2735 | AA6: 382
A7: Bürglen | B7: =C7+E7+G7+I7+M7+O7+Q7+S7 -> 1093 | C7: 168 | D7: =C7/(E7+C7) -> 0.50299401 | E7: 166 | F7: =E7/(C7+E7) -> 0.49700599 | G7: 106 | H7: =G7/(I7+G7) -> 0.64242424 | I7: 59 | J7: =I7/(G7+I7) -> 0.35757576 | K7: =A7 -> Bürglen | L7: =B7 -> 1093 | M7: 127 | N7: =M7/(O7+M7) -> 0.59345794 | O7: 87 | P7: =O7/(M7+O7) -> 0.40654206 | Q7: 247 | R7: =Q7/(S7+Q7) -> 0.65 | S7: 133 | T7: =S7/(Q7+S7) -> 0.35 | Y7: =-B7+Z7-AA7 -> 0 | Z7: 1297 | AA7: 204
A8: Erstfeld | B8: =C8+E8+G8+I8+M8+O8+Q8+S8 -> 910 | C8: 142 | D8: =C8/(E8+C8) -> 0.45079365 | E8: 173 | F8: =E8/(C8+E8) -> 0.54920635 | G8: 63 | H8: =G8/(I8+G8) -> 0.59433962 | I8: 43 | J8: =I8/(G8+I8) -> 0.40566038 | K8: =A8 -> Erstfeld | L8: =B8 -> 910 | M8: 196 | N8: =M8/(O8+M8) -> 0.7340824 | O8: 71 | P8: =O8/(M8+O8) -> 0.2659176 | Q8: 142 | R8: =Q8/(S8+Q8) -> 0.63963964 | S8: 80 | T8: =S8/(Q8+S8) -> 0.36036036 | Y8: =-B8+Z8-AA8 -> 0 | Z8: 1097 | AA8: 187
A9: Schattdorf | B9: =C9+E9+G9+I9+M9+O9+Q9+S9 -> 1319 | C9: 217 | D9: =C9/(E9+C9) -> 0.48654709 | E9: 229 | F9: =E9/(C9+E9) -> 0.51345291 | G9: 126 | H9: =G9/(I9+G9) -> 0.47908745 | I9: 137 | J9: =I9/(G9+I9) -> 0.52091255 | K9: =A9 -> Schattdorf | L9: =B9 -> 1319 | M9: 151 | N9: =M9/(O9+M9) -> 0.62396694 | O9: 91 | P9: =O9/(M9+O9) -> 0.37603306 | Q9: 207 | R9: =Q9/(S9+Q9) -> 0.5625 | S9: 161 | T9: =S9/(Q9+S9) -> 0.4375 | Y9: =-B9+Z9-AA9 -> 0 | Z9: 1572 | AA9: 253
A11: Total | B11: =SUM(B6:B9) -> 5675 | C11: =SUM(C6:C10) -> 778 | D11: =C11/(E11+C11) -> 0.44867359 | E11: =SUM(E6:E9) -> 956 | F11: =E11/(C11+E11) -> 0.55132641 | G11: =SUM(G6:G10) -> 512 | H11: =G11/(I11+G11) -> 0.48995215 | I11: =SUM(I6:I9) -> 533 | J11: =I11/(G11+I11) -> 0.51004785 | K11: =A11 -> Total | L11: =B11 -> 5675 | M11: =SUM(M6:M10) -> 931 | N11: =M11/(O11+M11) -> 0.64162646 | O11: =SUM(O6:O9) -> 520 | P11: =O11/(M11+O11) -> 0.35837354 | Q11: =SUM(Q6:Q10) -> 921 | R11: =Q11/(S11+Q11) -> 0.63737024 | S11: =SUM(S6:S9) -> 524 | T11: =S11/(Q11+S11) -> 0.36262976
A13: Gültige Wahlzettel mit Listenbezeichnung 2024
A14: Gemeinde | B14: Total | C14: CVP | G14: FDP | K14: Gemeinde | L14: Total | M14: GLP | Q14: SP/Grüne | U14: SVP
C15: unverändert | E15: verändert | G15: unverändert | I15: verändert | M15: unverändert | O15: verändert | Q15: unverändert | S15: verändert | U15: unverändert | W15: verändert | Y15: leer/ungültig | Z15: kontrolle | AA15: ohne
C16: abs. | D16: % | E16: abs. | F16: % | G16: abs. | H16: % | I16: abs. | J16: % | M16: abs. | N16: % | O16: abs. | P16: % | Q16: abs. | R16: % | S16: abs. | T16: % | U16: abs. | V16: % | W16: abs. | X16: %
A18: Altdorf | B18: =C18+E18+G18+I18+M18+O18+Q18+S18+U18+W18 -> 3033 | C18: 403 | D18: =C18/(E18+C18) -> 0.41718427 | E18: 563 | F18: =E18/(C18+E18) -> 0.58281573 | G18: 253 | H18: =G18/(I18+G18) -> 0.5292887 | I18: 225 | J18: =I18/(G18+I18) -> 0.4707113 | K18: =A18 -> Altdorf | L18: =B18 -> 3033 | M18: 157 | N18: =M18/(O18+M18) -> 0.4197861 | O18: 217 | P18: =O18/(M18+O18) -> 0.5802139 | Q18: 416 | R18: =Q18/(S18+Q18) -> 0.62368816 | S18: 251 | T18: =S18/(Q18+S18) -> 0.37631184 | U18: 376 | V18: =U18/(W18+U18) -> 0.68613139 | W18: 172 | X18: =W18/(U18+W18) -> 0.31386861 | Y18: =-B18+Z18-AA18 -> 0 | Z18: 3522 | AA18: 489
A19: Bürglen | B19: =C19+E19+G19+I19+M19+O19+Q19+S19+U19+W19 -> 1286 | C19: 134 | D19: =C19/(E19+C19) -> 0.4011976 | E19: 200 | F19: =E19/(C19+E19) -> 0.5988024 | G19: 69 | H19: =G19/(I19+G19) -> 0.44805195 | I19: 85 | J19: =I19/(G19+I19) -> 0.55194805 | K19: =A19 -> Bürglen | L19: =B19 -> 1286 | M19: 44 | N19: =M19/(O19+M19) -> 0.34375 | O19: 84 | P19: =O19/(M19+O19) -> 0.65625 | Q19: 118 | R19: =Q19/(S19+Q19) -> 0.64480874 | S19: 65 | T19: =S19/(Q19+S19) -> 0.35519126 | U19: 318 | V19: =U19/(W19+U19) -> 0.65297741 | W19: 169 | X19: =W19/(U19+W19) -> 0.34702259 | Y19: =-B19+Z19-AA19 -> 0 | Z19: 1589 | AA19: 303
A20: Erstfeld | B20: =C20+E20+G20+I20+M20+O20+Q20+S20+U20+W20 -> 1001 | C20: 118 | D20: =C20/(E20+C20) -> 0.472 | E20: 132 | F20: =E20/(C20+E20) -> 0.528 | G20: 97 | H20: =G20/(I20+G20) -> 0.5739645 | I20: 72 | J20: =I20/(G20+I20) -> 0.4260355 | K20: =A20 -> Erstfeld | L20: =B20 -> 1001 | M20: 0 | N20: 0 | O20: 0 | P20: 0 | Q20: 197 | R20: =Q20/(S20+Q20) -> 0.69611307 | S20: 86 | T20: =S20/(Q20+S20) -> 0.30388693 | U20: 162 | V20: =U20/(W20+U20) -> 0.54180602 | W20: 137 | X20: =W20/(U20+W20) -> 0.45819398 | Y20: =-B20+Z20-AA20 -> 0 | Z20: 1295 | AA20: 294
A21: Schattdorf | B21: =C21+E21+G21+I21+M21+O21+Q21+S21+U21+W21 -> 1599 | C21: 226 | D21: =C21/(E21+C21) -> 0.36569579 | E21: 392 | F21: =E21/(C21+E21) -> 0.63430421 | G21: 103 | H21: =G21/(I21+G21) -> 0.39163498 | I21: 160 | J21: =I21/(G21+I21) -> 0.60836502 | K21: =A21 -> Schattdorf | L21: =B21 -> 1599 | M21: 31 | N21: =M21/(O21+M21) -> 0.34444444 | O21: 59 | P21: =O21/(M21+O21) -> 0.65555556 | Q21: 125 | R21: =Q21/(S21+Q21) -> 0.6281407 | S21: 74 | T21: =S21/(Q21+S21) -> 0.3718593 | U21: 246 | V21: =U21/(W21+U21) -> 0.57342657 | W21: 183 | X21: =W21/(U21+W21) -> 0.42657343 | Y21: =-B21+Z21-AA21 -> 0 | Z21: 2009 | AA21: 410
A23: Total | B23: =SUM(B18:B21) -> 6919 | C23: =SUM(C18:C22) -> 881 | D23: =C23/(E23+C23) -> 0.40636531 | E23: =SUM(E18:E21) -> 1287 | F23: =E23/(C23+E23) -> 0.59363469 | G23: =SUM(G18:G22) -> 522 | H23: =G23/(I23+G23) -> 0.4906015 | I23: =SUM(I18:I21) -> 542 | J23: =I23/(G23+I23) -> 0.5093985 | K23: =A23 -> Total | L23: =B23 -> 6919 | M23: =SUM(M18:M22) -> 232 | N23: =M23/(O23+M23) -> 0.39189189 | O23: =SUM(O18:O21) -> 360 | P23: =O23/(M23+O23) -> 0.60810811 | Q23: =SUM(Q18:Q22) -> 856 | R23: =Q23/(S23+Q23) -> 0.64264264 | S23: =SUM(S18:S21) -> 476 | T23: =S23/(Q23+S23) -> 0.35735736 | U23: =SUM(U18:U22) -> 1102 | V23: =U23/(W23+U23) -> 0.6250709 | W23: =SUM(W18:W21) -> 661 | X23: =W23/(U23+W23) -> 0.3749291
Y28: =C18+G18+M18+Q18+U18 -> 1605
Y29: =E18+I18+O18+S18+W18 -> 1428

Sheet 6 Anteil unverändert Parteien
A2: Partei | B2: 1992 | C2: 1996 | D2: 2000 | E2: 2004 | F2: 2008 | G2: 2012 | H2: 2016 | I2: 2020 | J2: 2024
A3: CVP | B3: 19.8 | C3: 32 | D3: 38.8 | E3: 41.4 | F3: 46.4 | G3: 32.9 | H3: 41.7 | I3: ='6 Gültige WZ'!$D$11*100 -> 44.867359 | J3: ='6 Gültige WZ'!$D$23*100 -> 40.636531
A4: FDP | B4: 18 | C4: 30.7 | D4: 37.6 | E4: 38.3 | F4: 52.5 | G4: 49.8 | H4: 51.1 | I4: ='6 Gültige WZ'!$H$11*100 -> 48.995215 | J4: ='6 Gültige WZ'!$H$23*100 -> 49.06015
A5: GLP | J5: ='6 Gültige WZ'!$N$23*100 -> 39.189189
A6: SP/GB | B6: 27 | C6: 37.8 | D6: 41.8 | E6: 47 | F6: 61.8 | G6: 51.3 | H6: 63 | I6: ='6 Gültige WZ'!$N$11*100 -> 64.162646 | J6: ='6 Gültige WZ'!$R$23*100 -> 64.264264
A7: SVP | D7: 37.3 | E7: 42.1 | F7: 64.9 | G7: 58.1 | H7: 64.8 | I7: ='6 Gültige WZ'!$R$11*100 -> 63.737024 | J7: ='6 Gültige WZ'!$V$23*100 -> 62.50709

Sheet 6.2 Freie Listen
A1: Gültige, bezeichnete und freie Listen 2020 | L1: Gültige, bezeichnete und freie Listen 2024
A2: Gemeinde | B2: Gültige Wahlzettel | C2: Wahlzettel mit Listenbezeichnung | G2: Freie Listen | L2: Gemeinde | M2: Gültige Wahlzettel | N2: Wahlzettel mit Listenbezeichnung | R2: Freie Listen
C3: unverändert | E3: verändert | N3: unverändert | P3: verändert
C4: abs. | D4: % | E4: abs. | F4: % | G4: abs. | H4: % | N4: abs. | O4: % | P4: abs. | Q4: % | R4: abs. | S4: %
A6: Altdorf | B6: ='6 Gültige WZ'!Z6-'6 Gültige WZ'!Y6 -> 2735 | C6: ='6 Gültige WZ'!C6+'6 Gültige WZ'!G6+'6 Gültige WZ'!M6+'6 Gültige WZ'!Q6 -> 1250 | D6: =C6/$B6 -> 0.45703839 | E6: 1103 | F6: =E6/$B6 -> 0.40329068 | G6: 382 | H6: =G6/$B6 -> 0.13967093 | J6: =E6+G6 -> 1485 | L6: Altdorf | M6: ='6 Gültige WZ'!Z18-'6 Gültige WZ'!Y18 -> 3522 | N6: ='6 Gültige WZ'!C18+'6 Gültige WZ'!G18+'6 Gültige WZ'!M18+'6 Gültige WZ'!Q18+'6 Gültige WZ'!U18 -> 1605 | O6: =N6/$M6 -> 0.45570698 | P6: ='6 Gültige WZ'!E18+'6 Gültige WZ'!I18+'6 Gültige WZ'!O18+'6 Gültige WZ'!S18+'6 Gültige WZ'!W18 -> 1428 | Q6: =P6/$M6 -> 0.40545145 | R6: ='6 Gültige WZ'!AA18 -> 489 | S6: =R6/$M6 -> 0.13884157 | U6: =P6+R6 -> 1917
A7: Bürglen | B7: ='6 Gültige WZ'!Z7-'6 Gültige WZ'!Y7 -> 1297 | C7: ='6 Gültige WZ'!C7+'6 Gültige WZ'!G7+'6 Gültige WZ'!M7+'6 Gültige WZ'!Q7 -> 648 | D7: =C7/$B7 -> 0.49961449 | E7: 445 | F7: =E7/$B7 -> 0.34309946 | G7: 204 | H7: =G7/$B7 -> 0.15728604 | J7: =E7+G7 -> 649 | L7: Bürglen | M7: ='6 Gültige WZ'!Z19-'6 Gültige WZ'!Y19 -> 1589 | N7: ='6 Gültige WZ'!C19+'6 Gültige WZ'!G19+'6 Gültige WZ'!M19+'6 Gültige WZ'!Q19+'6 Gültige WZ'!U19 -> 683 | O7: =N7/$M7 -> 0.42983008 | P7: ='6 Gültige WZ'!E19+'6 Gültige WZ'!I19+'6 Gültige WZ'!O19+'6 Gültige WZ'!S19+'6 Gültige WZ'!W19 -> 603 | Q7: =P7/$M7 -> 0.37948395 | R7: ='6 Gültige WZ'!AA19 -> 303 | S7: =R7/$M7 -> 0.19068597 | U7: =P7+R7 -> 906
A8: Erstfeld | B8: ='6 Gültige WZ'!Z8-'6 Gültige WZ'!Y8 -> 1097 | C8: ='6 Gültige WZ'!C8+'6 Gültige WZ'!G8+'6 Gültige WZ'!M8+'6 Gültige WZ'!Q8 -> 543 | D8: =C8/$B8 -> 0.49498633 | E8: 367 | F8: =E8/$B8 -> 0.33454877 | G8: 187 | H8: =G8/$B8 -> 0.1704649 | J8: =E8+G8 -> 554 | L8: Erstfeld | M8: ='6 Gültige WZ'!Z20-'6 Gültige WZ'!Y20 -> 1295 | N8: ='6 Gültige WZ'!C20+'6 Gültige WZ'!G20+'6 Gültige WZ'!M20+'6 Gültige WZ'!Q20+'6 Gültige WZ'!U20 -> 574 | O8: =N8/$M8 -> 0.44324324 | P8: ='6 Gültige WZ'!E20+'6 Gültige WZ'!I20+'6 Gültige WZ'!O20+'6 Gültige WZ'!S20+'6 Gültige WZ'!W20 -> 427 | Q8: =P8/$M8 -> 0.32972973 | R8: ='6 Gültige WZ'!AA20 -> 294 | S8: =R8/$M8 -> 0.22702703 | U8: =P8+R8 -> 721
A9: Schattdorf | B9: ='6 Gültige WZ'!Z9-'6 Gültige WZ'!Y9 -> 1572 | C9: ='6 Gültige WZ'!C9+'6 Gültige WZ'!G9+'6 Gültige WZ'!M9+'6 Gültige WZ'!Q9 -> 701 | D9: =C9/$B9 -> 0.44592875 | E9: 618 | F9: =E9/$B9 -> 0.39312977 | G9: 253 | H9: =G9/$B9 -> 0.16094148 | J9: =E9+G9 -> 871 | L9: Schattdorf | M9: ='6 Gültige WZ'!Z21-'6 Gültige WZ'!Y21 -> 2009 | N9: ='6 Gültige WZ'!C21+'6 Gültige WZ'!G21+'6 Gültige WZ'!M21+'6 Gültige WZ'!Q21+'6 Gültige WZ'!U21 -> 731 | O9: =N9/$M9 -> 0.36386262 | P9: ='6 Gültige WZ'!E21+'6 Gültige WZ'!I21+'6 Gültige WZ'!O21+'6 Gültige WZ'!S21+'6 Gültige WZ'!W21 -> 868 | Q9: =P9/$M9 -> 0.43205575 | R9: ='6 Gültige WZ'!AA21 -> 410 | S9: =R9/$M9 -> 0.20408163 | U9: =P9+R9 -> 1278
J10: =E10+G10 -> 0 | U10: =P10+R10 -> 0
A11: Total | B11: =SUM(B6:B9) -> 6701 | C11: =SUM(C6:C10) -> 3142 | D11: =C11/$B11 -> 0.46888524 | E11: 2533 | F11: =E11/$B11 -> 0.37800328 | G11: 1026 | H11: =G11/$B11 -> 0.15311148 | J11: =E11+G11 -> 3559 | L11: Total | M11: =SUM(M6:M9) -> 8415 | N11: =SUM(N6:N10) -> 3593 | O11: =N11/$M11 -> 0.42697564 | P11: =SUM(P6:P10) -> 3326 | Q11: =P11/$M11 -> 0.39524658 | R11: =SUM(R6:R10) -> 1496 | S11: =R11/$M11 -> 0.17777778 | U11: =P11+R11 -> 4822

Sheet 6.2.1 Freie Liste - Verteilung
A1: 2020 Verteilung der Listenstimmen von Freien Listen auf die Parteien (aus form 3b) | V1: Aus auswertung 2 rauskopieren | AM1: Gemeinde | AN1: CVP | AP1: FDP | AT1: SP/GB | AV1: SVP
A2: Gemeinde | B2: Total | C2: Kandidatenstimmen | H2: Leere Linien | J2: Gemeinde | K2: CVP | M2: FDP | Q2: SP/GB | S2: SVP | V2: Gemeinde | W2: CVP | Z2: FDP | AF2: SP/GB | AI2: SVP | AN2: Parteistimmen | AP2: Parteistimmen | AT2: Parteistimmen | AV2: Parteistimmen
C3: CVP | D3: FDP | F3: SP/GB | G3: SVP | K3: Parteistärke in % | L3: Freie Liste in % | M3: Parteistärke in % | N3: Freie Liste in % | Q3: Parteistärke in % | R3: Freie Liste in % | S3: Parteistärke in % | T3: Freie Liste in % | W3: Kandidaten-stimmen | X3: Zusatzstimmen | Y3: in % | Z3: Kandidaten-stimmen | AA3: Zusatzstimmen | AB3: in % | AF3: Kandidaten-stimmen | AG3: Zusatzstimmen | AH3: in % | AI3: Kandidaten-stimmen | AJ3: Zusatzstimmen | AK3: in % | AN3: absolut | AO3: in % | AP3: absolut | AQ3: in % | AT3: absolut | AU3: in % | AV3: absolut | AW3: in %
A5: Altdorf | B5: ='6.2 Freie Listen'!G6*15 -> 5730 | C5: 1801 | D5: 1476 | F5: 1164 | G5: 612 | H5: =B5-C5-D5-F5-G5 -> 677 | J5: Altdorf | K5: ='722 Verteilung Gden'!G7 -> 28.430158 | L5: =C5/B5% -> 31.431065 | M5: ='722 Verteilung Gden'!G8 -> 22.833846 | N5: =D5/$B5% -> 25.759162 | Q5: ='722 Verteilung Gden'!G9 -> 29.513235 | R5: =F5/$B5% -> 20.314136 | S5: ='722 Verteilung Gden'!G10 -> 19.222762 | T5: =G5/$B5% -> 10.680628 | V5: Altdorf | W5: 10683 | X5: 788 | Y5: =X5/W5% -> 7.3762052 | Z5: 8731 | AA5: 482 | AB5: =AA5/Z5% -> 5.5205589 | AF5: 11659 | AG5: 249 | AH5: =AG5/AF5% -> 2.1356892 | AI5: 7351 | AJ5: 405 | AK5: =AJ5/AI5% -> 5.5094545 | AM5: Altdorf | AN5: =W5+X5 -> 11471 | AO5: =AN5/SUM($AN5+$AP5+$AT5+$AV5)% -> 28.430158 | AP5: =Z5+AA5 -> 9213 | AQ5: =AP5/SUM($AN5+$AP5+$AT5+$AV5)% -> 22.833846 | AT5: =AF5+AG5 -> 11908 | AU5: =AT5/SUM($AN5+$AP5+$AT5+$AV5)% -> 29.513235 | AV5: =AI5+AJ5 -> 7756 | AW5: =AV5/SUM($AN5+$AP5+$AT5+$AV5)% -> 19.222762 | AY5: =SUM(AW5+AU5+AQ5+AO5) -> 100
A6: Bürglen | B6: ='6.2 Freie Listen'!G7*7 -> 1428 | C6: 520 | D6: 257 | F6: 146 | G6: 366 | H6: =B6-C6-D6-F6-G6 -> 139 | J6: Bürglen | K6: ='722 Verteilung Gden'!G12 -> 31.565996 | L6: =C6/B6% -> 36.414566 | M6: ='722 Verteilung Gden'!G13 -> 17.527964 | N6: =D6/$B6% -> 17.997199 | Q6: ='722 Verteilung Gden'!G14 -> 17.964206 | R6: =F6/$B6% -> 10.22409 | S6: ='722 Verteilung Gden'!G15 -> 32.941834 | T6: =G6/$B6% -> 25.630252 | V6: Bürglen | W6: 2740 | X6: 82 | Y6: =X6/W6% -> 2.9927007 | Z6: 1519 | AA6: 48 | AB6: =AA6/Z6% -> 3.1599737 | AF6: 1549 | AG6: 57 | AH6: =AG6/AF6% -> 3.6797934 | AI6: 2786 | AJ6: 159 | AK6: =AJ6/AI6% -> 5.707107 | AM6: Bürglen | AN6: =W6+X6 -> 2822 | AO6: =AN6/SUM($AN6+$AP6+$AT6+$AV6)% -> 31.565996 | AP6: =Z6+AA6 -> 1567 | AQ6: =AP6/SUM($AN6+$AP6+$AT6+$AV6)% -> 17.527964 | AT6: =AF6+AG6 -> 1606 | AU6: =AT6/SUM($AN6+$AP6+$AT6+$AV6)% -> 17.964206 | AV6: =AI6+AJ6 -> 2945 | AW6: =AV6/SUM($AN6+$AP6+$AT6+$AV6)% -> 32.941834 | AY6: =SUM(AW6+AU6+AQ6+AO6) -> 100
A7: Erstfeld | B7: ='6.2 Freie Listen'!G8*6 -> 1122 | C7: 402 | D7: 237 | F7: 167 | G7: 267 | H7: =B7-C7-D7-F7-G7 -> 49 | J7: Erstfeld | K7: ='722 Verteilung Gden'!G17 -> 35.34364 | L7: =C7/B7% -> 35.828877 | M7: ='722 Verteilung Gden'!G18 -> 14.480331 | N7: =D7/$B7% -> 21.122995 | Q7: ='722 Verteilung Gden'!G19 -> 26.09827 | R7: =F7/$B7% -> 14.884135 | S7: ='722 Verteilung Gden'!G20 -> 24.077759 | T7: =G7/$B7% -> 23.796791 | V7: Erstfeld | W7: 2227 | X7: 82 | Y7: =X7/W7% -> 3.6820835 | Z7: 925 | AA7: 21 | AB7: =AA7/Z7% -> 2.2702703 | AF7: 1647 | AG7: 58 | AH7: =AG7/AF7% -> 3.5215543 | AI7: 1533 | AJ7: 40 | AK7: =AJ7/AI7% -> 2.6092629 | AM7: Erstfeld | AN7: =W7+X7 -> 2309 | AO7: =AN7/SUM($AN7+$AP7+$AT7+$AV7)% -> 35.34364 | AP7: =Z7+AA7 -> 946 | AQ7: =AP7/SUM($AN7+$AP7+$AT7+$AV7)% -> 14.480331 | AT7: =AF7+AG7 -> 1705 | AU7: =AT7/SUM($AN7+$AP7+$AT7+$AV7)% -> 26.09827 | AV7: =AI7+AJ7 -> 1573 | AW7: =AV7/SUM($AN7+$AP7+$AT7+$AV7)% -> 24.077759 | AY7: =SUM(AW7+AU7+AQ7+AO7) -> 100
A8: Schattdorf | B8: ='6.2 Freie Listen'!G9*9 -> 2277 | C8: 751 | D8: 557 | F8: 345 | G8: 329 | H8: =B8-C8-D8-F8-G8 -> 295 | J8: Schattdorf | K8: ='722 Verteilung Gden'!G22 -> 34.606222 | L8: =C8/B8% -> 32.981994 | M8: ='722 Verteilung Gden'!G23 -> 21.374432 | N8: =D8/$B8% -> 24.462011 | Q8: ='722 Verteilung Gden'!G24 -> 18.768498 | R8: =F8/$B8% -> 15.151515 | S8: ='722 Verteilung Gden'!G25 -> 25.250848 | T8: =G8/$B8% -> 14.448836 | V8: Schattdorf | W8: 4613 | X8: 181 | Y8: =X8/W8% -> 3.9236939 | Z8: 2874 | AA8: 87 | AB8: =AA8/Z8% -> 3.0271399 | AF8: 2481 | AG8: 119 | AH8: =AG8/AF8% -> 4.796453 | AI8: 3298 | AJ8: 200 | AK8: =AJ8/AI8% -> 6.0642814 | AM8: Schattdorf | AN8: =W8+X8 -> 4794 | AO8: =AN8/SUM($AN8+$AP8+$AT8+$AV8)% -> 34.606222 | AP8: =Z8+AA8 -> 2961 | AQ8: =AP8/SUM($AN8+$AP8+$AT8+$AV8)% -> 21.374432 | AT8: =AF8+AG8 -> 2600 | AU8: =AT8/SUM($AN8+$AP8+$AT8+$AV8)% -> 18.768498 | AV8: =AI8+AJ8 -> 3498 | AW8: =AV8/SUM($AN8+$AP8+$AT8+$AV8)% -> 25.250848 | AY8: =SUM(AW8+AU8+AQ8+AO8) -> 100
A10: Total | B10: =SUM(B5:B8) -> 10557 | C10: =SUM(C5:C9) -> 3474 | D10: =SUM(D5:D9) -> 2527 | F10: =SUM(F5:F9) -> 1822 | G10: =SUM(G5:G9) -> 1574 | H10: =SUM(H5:H9) -> 1160 | J10: Total | K10: ='722 Verteilung Gden'!V6 -> 30.708729 | L10: =C10/B10% -> 32.907076 | M10: ='722 Verteilung Gden'!V7 -> 21.079599 | N10: =D10/$B10% -> 23.936724 | Q10: ='722 Verteilung Gden'!V8 -> 25.57482 | R10: =F10/$B10% -> 17.258691 | S10: ='722 Verteilung Gden'!V9 -> 22.636852 | T10: =G10/$B10% -> 14.909539 | V10: Total | W10: =SUM(W5:W8) -> 20263 | X10: =SUM(X5:X9) -> 1133 | Y10: =X10/W10% -> 5.5914721 | Z10: =SUM(Z5:Z9) -> 14049 | AA10: =SUM(AA5:AA9) -> 638 | AB10: =AA10/Z10% -> 4.5412485 | AF10: =SUM(AF5:AF8) -> 17336 | AG10: =SUM(AG5:AG9) -> 483 | AH10: =AG10/AF10% -> 2.7861098 | AI10: =SUM(AI5:AI9) -> 14968 | AJ10: =SUM(AJ5:AJ9) -> 804 | AK10: =AJ10/AI10% -> 5.3714591 | AM10: Total | AN10: =SUM(AN5:AN8) -> 21396 | AO10: =AN10/SUM($AN10+$AP10+$AT10+$AV10)% -> 30.708729 | AP10: =SUM(AP5:AP8) -> 14687 | AQ10: =AP10/SUM($AN10+$AP10+$AT10+$AV10)% -> 21.079599 | AT10: =SUM(AT5:AT8) -> 17819 | AU10: =AT10/SUM($AN10+$AP10+$AT10+$AV10)% -> 25.57482 | AV10: =SUM(AV5:AV8) -> 15772 | AW10: =AV10/SUM($AN10+$AP10+$AT10+$AV10)% -> 22.636852
W11: =W10+X10 -> 21396 | Z11: =Z10+AA10 -> 14687 | AF11: =AF10+AG10 -> 17819 | AI11: =AI10+AJ10 -> 15772
A14: 2024 Verteilung der Listenstimmen von Freien Listen auf die Parteien (aus form 3b) | V14: Aus Formular 2 (pro Gemeinde) | AM14: Gemeinde | AN14: CVP | AP14: FDP | AR14: GLP | AT14: SP/GB | AV14: SVP
A15: Gemeinde | B15: Total | C15: Kandidatenstimmen | H15: Leere Linien | J15: Gemeinde | K15: CVP | M15: FDP | O15: GLP | Q15: SP/GB | S15: SVP | V15: Gemeinde | W15: CVP | Z15: FDP | AC15: GLP | AF15: SP/GB | AI15: SVP | AN15: Parteistimmen | AP15: Parteistimmen | AR15: Parteistimmen | AT15: Parteistimmen | AV15: Parteistimmen
C16: CVP | D16: FDP | E16: GLP | F16: SP/GB | G16: SVP | K16: Parteistärke in % | L16: Freie Liste in % | M16: Parteistärke in % | N16: Freie Liste in % | O16: Parteistärke in % | P16: Freie Liste in % | Q16: Parteistärke in % | R16: Freie Liste in % | S16: Parteistärke in % | T16: Freie Liste in % | W16: Kandidaten-stimmen | X16: Zusatzstimmen | Y16: in % | Z16: Kandidaten-stimmen | AA16: Zusatzstimmen | AB16: in % | AC16: Kandidaten-stimmen | AD16: Zusatzstimmen | AE16: in % | AF16: Kandidaten-stimmen | AG16: Zusatzstimmen | AH16: in % | AI16: Kandidaten-stimmen | AJ16: Zusatzstimmen | AK16: in % | AN16: absolut | AO16: in % | AP16: absolut | AQ16: in % | AR16: absolut | AS16: in % | AT16: absolut | AU16: in % | AV16: absolut | AW16: in %
A18: Altdorf | B18: ='6.2 Freie Listen'!R6*15 -> 7335 | C18: 2113 | D18: 1265 | E18: 933 | F18: 921 | G18: 653 | H18: =B18-C18-D18-E18-F18-G18 -> 1450 | J18: Altdorf | K18: ='722 Verteilung Gden'!G38 -> 32.113663 | L18: =C18/B18% -> 28.807089 | M18: ='722 Verteilung Gden'!G39 -> 17.391981 | N18: =D18/$B18% -> 17.24608 | O18: ='722 Verteilung Gden'!G40 -> 12.588556 | P18: =E18/$B18% -> 12.719836 | Q18: ='722 Verteilung Gden'!G41 -> 20.587777 | R18: =F18/$B18% -> 12.556237 | S18: ='722 Verteilung Gden'!G42 -> 17.318023 | T18: =G18/$B18% -> 8.9025222 | V18: Altdorf | W18: 15545 | X18: 955 | Y18: =X18/W18% -> 6.1434545 | Z18: 8378 | AA18: 558 | AB18: =AA18/Z18% -> 6.6603008 | AC18: 5988 | AD18: 480 | AE18: =AD18/AC18% -> 8.0160321 | AF18: 10131 | AG18: 447 | AH18: =AG18/AF18% -> 4.4122002 | AI18: 8169 | AJ18: 729 | AK18: =AJ18/AI18% -> 8.9239809 | AM18: Altdorf | AN18: =W18+X18 -> 16500 | AO18: =AN18/SUM($AN18+$AP18+$AR18+$AT18+$AV18)% -> 32.113663 | AP18: =Z18+AA18 -> 8936 | AQ18: =AP18/SUM($AN18+$AP18+$AR18+$AT18+$AV18)% -> 17.391981 | AR18: =AC18+AD18 -> 6468 | AS18: =AR18/SUM($AN18+$AR18+$AP18+$AT18+$AV18)% -> 12.588556 | AT18: =AF18+AG18 -> 10578 | AU18: =AT18/SUM($AN18+$AP18+$AR18+$AT18+$AV18)% -> 20.587777 | AV18: =AI18+AJ18 -> 8898 | AW18: =AV18/SUM($AN18+$AP18+$AR18+$AT18+$AV18)% -> 17.318023 | AY18: =SUM(AS18+AW18+AU18+AQ18+AO18) -> 100
A19: Bürglen | B19: ='6.2 Freie Listen'!R7*7 -> 2121 | C19: 572 | D19: 394 | E19: 243 | F19: 167 | G19: 510 | H19: =B19-C19-D19-E19-F19-G19 -> 235 | J19: Bürglen | K19: ='722 Verteilung Gden'!G44 -> 26.377663 | L19: =C19/B19% -> 26.968411 | M19: ='722 Verteilung Gden'!G45 -> 14.704262 | N19: =D19/$B19% -> 18.576143 | O19: ='722 Verteilung Gden'!G46 -> 11.195812 | P19: =E19/$B19% -> 11.45686 | Q19: ='722 Verteilung Gden'!G47 -> 12.81227 | R19: =F19/$B19% -> 7.8736445 | S19: ='722 Verteilung Gden'!G48 -> 34.909993 | T19: =G19/$B19% -> 24.045262 | V19: Bürglen | W19: 2656 | X19: 216 | Y19: =X19/W19% -> 8.1325301 | Z19: 1546 | AA19: 55 | AB19: =AA19/Z19% -> 3.5575679 | AC19: 1180 | AD19: 39 | AE19: =AD19/AC19% -> 3.3050847 | AF19: 1383 | AG19: 12 | AH19: =AG19/AF19% -> 0.86767896 | AI19: 3592 | AJ19: 209 | AK19: =AJ19/AI19% -> 5.8184855 | AM19: Bürglen | AN19: =W19+X19 -> 2872 | AO19: =AN19/SUM($AN19+$AP19+$AR19+$AT19+$AV19)% -> 26.377663 | AP19: =Z19+AA19 -> 1601 | AQ19: =AP19/SUM($AN19+$AP19+$AR19+$AT19+$AV19)% -> 14.704262 | AR19: =AC19+AD19 -> 1219 | AS19: =AR19/SUM($AN19+$AR19+$AP19+$AT19+$AV19)% -> 11.195812 | AT19: =AF19+AG19 -> 1395 | AU19: =AT19/SUM($AN19+$AP19+$AR19+$AT19+$AV19)% -> 12.81227 | AV19: =AI19+AJ19 -> 3801 | AW19: =AV19/SUM($AN19+$AP19+$AR19+$AT19+$AV19)% -> 34.909993 | AY19: =SUM(AS19+AW19+AU19+AQ19+AO19) -> 100
A20: Erstfeld | B20: ='6.2 Freie Listen'!R8*6 -> 1764 | C20: 402 | D20: 459 | E20: 0 | F20: 389 | G20: 365 | H20: =B20-C20-D20-E20-F20-G20 -> 149 | J20: Erstfeld | K20: ='722 Verteilung Gden'!G50 -> 24.642435 | L20: =C20/B20% -> 22.789116 | M20: ='722 Verteilung Gden'!G51 -> 20.391025 | N20: =D20/$B20% -> 26.020408 | O20: ='722 Verteilung Gden'!G52 -> 0 | P20: =E20/$B20% -> 0 | Q20: ='722 Verteilung Gden'!G53 -> 28.303372 | R20: =F20/$B20% -> 22.052154 | S20: ='722 Verteilung Gden'!G54 -> 26.663168 | T20: =G20/$B20% -> 20.69161 | V20: Erstfeld | W20: 1772 | X20: 106 | Y20: =X20/W20% -> 5.9819413 | Z20: 1518 | AA20: 36 | AB20: =AA20/Z20% -> 2.3715415 | AF20: 2133 | AG20: 24 | AH20: =AG20/AF20% -> 1.1251758 | AI20: 1940 | AJ20: 92 | AK20: =AJ20/AI20% -> 4.742268 | AM20: Erstfeld | AN20: =W20+X20 -> 1878 | AO20: =AN20/SUM($AN20+$AP20+$AR20+$AT20+$AV20)% -> 24.642435 | AP20: =Z20+AA20 -> 1554 | AQ20: =AP20/SUM($AN20+$AP20+$AR20+$AT20+$AV20)% -> 20.391025 | AT20: =AF20+AG20 -> 2157 | AU20: =AT20/SUM($AN20+$AP20+$AR20+$AT20+$AV20)% -> 28.303372 | AV20: =AI20+AJ20 -> 2032 | AW20: =AV20/SUM($AN20+$AP20+$AR20+$AT20+$AV20)% -> 26.663168 | AY20: =SUM(AS20+AW20+AU20+AQ20+AO20) -> 100
A21: Schattdorf | B21: ='6.2 Freie Listen'!R9*9 -> 3690 | C21: 1154 | D21: 851 | E21: 180 | F21: 443 | G21: 497 | H21: =B21-C21-D21-E21-F21-G21 -> 565 | J21: Schattdorf | K21: ='722 Verteilung Gden'!G56 -> 38.290706 | L21: =C21/B21% -> 31.273713 | M21: ='722 Verteilung Gden'!G57 -> 19.365152 | N21: =D21/$B21% -> 23.062331 | O21: ='722 Verteilung Gden'!G58 -> 5.1667047 | P21: =E21/$B21% -> 4.8780488 | Q21: ='722 Verteilung Gden'!G59 -> 13.461978 | R21: =F21/$B21% -> 12.00542 | S21: ='722 Verteilung Gden'!G60 -> 23.71546 | T21: =G21/$B21% -> 13.468835 | V21: Schattdorf | W21: 5979 | X21: 728 | Y21: =X21/W21% -> 12.175949 | Z21: 3268 | AA21: 124 | AB21: =AA21/Z21% -> 3.7943696 | AC21: 724 | AD21: 181 | AE21: =AD21/AC21% -> 25 | AF21: 2279 | AG21: 79 | AH21: =AG21/AF21% -> 3.4664326 | AI21: 3921 | AJ21: 233 | AK21: =AJ21/AI21% -> 5.9423616 | AM21: Schattdorf | AN21: =W21+X21 -> 6707 | AO21: =AN21/SUM($AN21+$AP21+$AR21+$AT21+$AV21)% -> 38.290706 | AP21: =Z21+AA21 -> 3392 | AQ21: =AP21/SUM($AN21+$AP21+$AR21+$AT21+$AV21)% -> 19.365152 | AR21: =AC21+AD21 -> 905 | AS21: =AR21/SUM($AN21+$AP21+$AR21+$AT21+$AV21)% -> 5.1667047 | AT21: =AF21+AG21 -> 2358 | AU21: =AT21/SUM($AN21+$AP21+$AR21+$AT21+$AV21)% -> 13.461978 | AV21: =AI21+AJ21 -> 4154 | AW21: =AV21/SUM($AN21+$AP21+$AR21+$AT21+$AV21)% -> 23.71546 | AY21: =SUM(AS21+AW21+AU21+AQ21+AO21) -> 100
A23: Total | B23: =SUM(B18:B21) -> 14910 | C23: =SUM(C18:C22) -> 4241 | D23: =SUM(D18:D22) -> 2969 | E23: =SUM(E18:E22) -> 1356 | F23: =SUM(F18:F22) -> 1920 | G23: =SUM(G18:G22) -> 2025 | H23: =SUM(H18:H22) -> 2399 | J23: Total | K23: ='722 Verteilung Gden'!V37 -> 31.985584 | L23: =C23/B23% -> 28.443997 | M23: ='722 Verteilung Gden'!V38 -> 17.71409 | N23: =D23/$B23% -> 19.91281 | O23: ='722 Verteilung Gden'!V39 -> 9.8301013 | P23: =E23/$B23% -> 9.0945674 | Q23: ='722 Verteilung Gden'!V40 -> 18.863909 | R23: =F23/$B23% -> 12.877264 | S23: ='722 Verteilung Gden'!V41 -> 21.606315 | T23: =G23/$B23% -> 13.581489 | V23: Total | W23: =SUM(W18:W21) -> 25952 | X23: =SUM(X18:X22) -> 2005 | Y23: =X23/W23% -> 7.7258015 | Z23: =SUM(Z18:Z22) -> 14710 | AA23: =SUM(AA18:AA22) -> 773 | AB23: =AA23/Z23% -> 5.2549286 | AC23: =SUM(AC18:AC22) -> 7892 | AD23: =SUM(AD18:AD22) -> 700 | AE23: =AD23/AC23% -> 8.8697415 | AF23: =SUM(AF18:AF21) -> 15926 | AG23: =SUM(AG18:AG22) -> 562 | AH23: =AG23/AF23% -> 3.5288208 | AI23: =SUM(AI18:AI22) -> 17622 | AJ23: =SUM(AJ18:AJ22) -> 1263 | AK23: =AJ23/AI23% -> 7.1671774 | AM23: Total | AN23: =SUM(AN18:AN21) -> 27957 | AO23: =AN23/SUM($AN23+$AP23+$AR23+$AT23+$AV23)% -> 31.985584 | AP23: =SUM(AP18:AP21) -> 15483 | AQ23: =AP23/SUM($AN23+$AP23+$AR23+$AT23+$AV23)% -> 17.71409 | AR23: =SUM(AR18:AR21) -> 8592 | AS23: =AR23/SUM($AN23+$AR23+$AP23+$AT23+$AV23)% -> 9.8301013 | AT23: =SUM(AT18:AT21) -> 16488 | AU23: =AT23/SUM($AN23+$AP23+$AR23+$AT23+$AV23)% -> 18.863909 | AV23: =SUM(AV18:AV21) -> 18885 | AW23: =AV23/SUM($AN23+$AP23+$AR23+$AT23+$AV23)% -> 21.606315
A24: fertig | J24: fertig | V24: fertig | W24: =W23+X23 -> 27957 | Z24: =Z23+AA23 -> 15483 | AC24: =AC23+AD23 -> 8592 | AF24: =AF23+AG23 -> 16488 | AI24: =AI23+AJ23 -> 18885 | AM24: fertig
C27: =B18-H18 -> 5885

Sheet 722 Verteilung Gden
A1: Listenstimmen Total | F1: 2020 manuell
A2: Partei | B2: Parteistärke | H2: Sitze | P2: Partei | Q2: Parteistärke | W2: Sitze
B3: 2012 | D3: 2016 | F3: 2020 | H3: 2012 | J3: 2016 | L3: 2020 | Q3: 2012 | S3: 2016 | U3: 2020 | W3: =Q3 -> 2012 | Y3: =S3 -> 2016 | AA3: =U3 -> 2020
B4: abs. | C4: % | D4: abs. | E4: % | F4: abs. | G4: % | H4: abs. | I4: % | J4: abs. | K4: % | L4: abs. | M4: % | Q4: abs. | R4: % | S4: abs. | T4: % | U4: abs. | V4: % | W4: abs. | X4: % | Y4: abs. | Z4: % | AA4: abs. | AB4: %
A6: Altdorf | P6: CVP | Q6: =SUMIF($A$7:$A$25,P6,B$7:B$25) -> 26311 | R6: =Q6/SUM(Q$6:Q$9)% -> 34.606532 | S6: =SUMIF($A$7:$A$25,$P6,D$7:D$25) -> 29070 | T6: =S6/SUM(S$6:S$9)% -> 30.666174 | U6: =SUMIF($A$7:$A$25,$P6,F$7:F$25) -> 21396 | V6: =U6/SUM(U$6:U$9)% -> 30.708729 | W6: =SUMIF($A$7:$A$25,$P6,H$7:H$25) -> 13 | X6: =W6/SUM(W$6:W$9)% -> 35.135135 | Y6: =SUMIF($A$7:$A$25,$P6,J$7:J$25) -> 12 | Z6: =Y6/SUM(Y$6:Y$9)% -> 32.432432 | AA6: =SUMIF($A$7:$A$25,$P6,L$7:L$25) -> 12 | AB6: =AA6/SUM(AA$6:AA$9)% -> 32.432432
A7: CVP | B7: 15560 | C7: 34.942735 | D7: 16586 | E7: 30.68924 | F7: 11471 | G7: =F7/SUM(F$7:F$10)% -> 28.430158 | H7: 5 | I7: 33.333333 | J7: 5 | K7: 33.333333 | L7: 5 | M7: =L7/SUM(L$7:L$10)% -> 33.333333 | P7: FDP | Q7: =SUMIF($A$7:$A$25,P7,B$7:B$25) -> 15115 | R7: =Q7/SUM(Q$6:Q$9)% -> 19.880572 | S7: =SUMIF($A$7:$A$25,$P7,D$7:D$25) -> 19065 | T7: =S7/SUM(S$6:S$9)% -> 20.11182 | U7: =SUMIF($A$7:$A$25,$P7,F$7:F$25) -> 14687 | V7: =U7/SUM(U$6:U$9)% -> 21.079599 | W7: =SUMIF($A$7:$A$25,$P7,H$7:H$25) -> 6 | X7: =W7/SUM(W$6:W$9)% -> 16.216216 | Y7: =SUMIF($A$7:$A$25,$P7,J$7:J$25) -> 7 | Z7: =Y7/SUM(Y$6:Y$9)% -> 18.918919 | AA7: =SUMIF($A$7:$A$25,$P7,L$7:L$25) -> 7 | AB7: =AA7/SUM(AA$6:AA$9)% -> 18.918919
A8: FDP | B8: 10392 | C8: 23.337076 | D8: 11434 | E8: 21.156444 | F8: 9213 | G8: =F8/SUM(F$7:F$10)% -> 22.833846 | H8: 3 | I8: 20 | J8: 3 | K8: 20 | L8: 3 | M8: =L8/SUM(L$7:L$10)% -> 20 | P8: SP/GB | Q8: =SUMIF($A$7:$A$25,P8,B$7:B$25) -> 17224 | R8: =Q8/SUM(Q$6:Q$9)% -> 22.654513 | S8: =SUMIF($A$7:$A$25,$P8,D$7:D$25) -> 22578 | T8: =S8/SUM(S$6:S$9)% -> 23.817712 | U8: =SUMIF($A$7:$A$25,$P8,F$7:F$25) -> 17819 | V8: =U8/SUM(U$6:U$9)% -> 25.57482 | W8: =SUMIF($A$7:$A$25,$P8,H$7:H$25) -> 9 | X8: =W8/SUM(W$6:W$9)% -> 24.324324 | Y8: =SUMIF($A$7:$A$25,$P8,J$7:J$25) -> 8 | Z8: =Y8/SUM(Y$6:Y$9)% -> 21.621622 | AA8: =SUMIF($A$7:$A$25,$P8,L$7:L$25) -> 9 | AB8: =AA8/SUM(AA$6:AA$9)% -> 24.324324
A9: SP/GB | B9: 10534 | C9: 23.655962 | D9: 14462 | E9: 26.759182 | F9: 11908 | G9: =F9/SUM(F$7:F$10)% -> 29.513235 | H9: 4 | I9: 26.666667 | J9: 4 | K9: 26.666667 | L9: 4 | M9: =L9/SUM(L$7:L$10)% -> 26.666667 | P9: SVP | Q9: =SUMIF($A$7:$A$25,P9,B$7:B$25) -> 17379 | R9: =Q9/SUM(Q$6:Q$9)% -> 22.858383 | S9: =SUMIF($A$7:$A$25,$P9,D$7:D$25) -> 24082 | T9: =S9/SUM(S$6:S$9)% -> 25.404293 | U9: =SUMIF($A$7:$A$25,$P9,F$7:F$25) -> 15772 | V9: =U9/SUM(U$6:U$9)% -> 22.636852 | W9: =SUMIF($A$7:$A$25,$P9,H$7:H$25) -> 9 | X9: =W9/SUM(W$6:W$9)% -> 24.324324 | Y9: =SUMIF($A$7:$A$25,$P9,J$7:J$25) -> 10 | Z9: =Y9/SUM(Y$6:Y$9)% -> 27.027027 | AA9: =SUMIF($A$7:$A$25,$P9,L$7:L$25) -> 9 | AB9: =AA9/SUM(AA$6:AA$9)% -> 24.324324
A10: SVP | B10: 8044 | C10: 18.064226 | D10: 11563 | E10: 21.395134 | F10: 7756 | G10: =F10/SUM(F$7:F$10)% -> 19.222762 | H10: 3 | I10: 20 | J10: 3 | K10: 20 | L10: 3 | M10: =L10/SUM(L$7:L$10)% -> 20
A11: Bürglen | P11: Total | Q11: =SUM(Q6:Q10) -> 76029 | S11: =SUM(S6:S10) -> 94795 | U11: =SUM(U6:U10) -> 69674 | W11: =SUM(W6:W10) -> 37 | Y11: =SUM(Y6:Y10) -> 37 | AA11: =SUM(AA6:AA10) -> 37
A12: CVP | B12: 3562 | C12: 36.559581 | D12: 3567 | E12: 29.016513 | F12: 2822 | G12: =F12/SUM(F$12:F$15)% -> 31.565996 | H12: 3 | I12: 42.857143 | J12: 2 | K12: 28.571429 | L12: 2 | M12: =L12/SUM(L$12:L$15)% -> 28.571429
A13: FDP | B13: 1156 | C13: 11.864929 | D13: 2272 | E13: 18.482063 | F13: 1567 | G13: =F13/SUM(F$12:F$15)% -> 17.527964 | H13: 1 | I13: 14.285714 | J13: 1 | K13: 14.285714 | L13: 1 | M13: =L13/SUM(L$12:L$15)% -> 14.285714
A14: SP/GB | B14: 1948 | C14: 19.993842 | D14: 2465 | E14: 20.052062 | F14: 1606 | G14: =F14/SUM(F$12:F$15)% -> 17.964206 | H14: 1 | I14: 14.285714 | J14: 1 | K14: 14.285714 | L14: 1 | M14: =L14/SUM(L$12:L$15)% -> 14.285714
A15: SVP | B15: 3077 | C15: 31.581648 | D15: 3989 | E15: 32.449361 | F15: 2945 | G15: =F15/SUM(F$12:F$15)% -> 32.941834 | H15: 2 | I15: 28.571429 | J15: 3 | K15: 42.857143 | L15: 3 | M15: =L15/SUM(L$12:L$15)% -> 42.857143
A16: Erstfeld
A17: CVP | B17: 2106 | C17: 30.072826 | D17: 2630 | E17: 30.16055 | F17: 2309 | G17: =F17/SUM(F$17:F$20)% -> 35.34364 | H17: 2 | I17: 33.333333 | J17: 2 | K17: 33.333333 | L17: 2 | M17: =L17/SUM(L$17:L$20)% -> 33.333333
A18: FDP | B18: 1214 | C18: 17.335428 | D18: 1425 | E18: 16.341743 | F18: 946 | G18: =F18/SUM(F$17:F$20)% -> 14.480331 | H18: 1 | I18: 16.666667 | J18: 1 | K18: 16.666667 | L18: 1 | M18: =L18/SUM(L$17:L$20)% -> 16.666667
A19: SP/GB | B19: 2110 | C19: 30.129944 | D19: 2342 | E19: 26.857798 | F19: 1705 | G19: =F19/SUM(F$17:F$20)% -> 26.09827 | H19: 2 | I19: 33.333333 | J19: 2 | K19: 33.333333 | L19: 2 | M19: =L19/SUM(L$17:L$20)% -> 33.333333
A20: SVP | B20: 1573 | C20: 22.461802 | D20: 2323 | E20: 26.639908 | F20: 1573 | G20: =F20/SUM(F$17:F$20)% -> 24.077759 | H20: 1 | I20: 16.666667 | J20: 1 | K20: 16.666667 | L20: 1 | M20: =L20/SUM(L$17:L$20)% -> 16.666667
A21: Schattdorf
A22: CVP | B22: 5083 | C22: 34.454009 | D22: 6287 | E22: 31.853879 | F22: 4794 | G22: =F22/SUM(F$22:F$25)% -> 34.606222 | H22: 3 | I22: 33.333333 | J22: 3 | K22: 33.333333 | L22: 3 | M22: =L22/SUM(L$22:L$25)% -> 33.333333
A23: FDP | B23: 2353 | C23: 15.949298 | D23: 3934 | E23: 19.932107 | F23: 2961 | G23: =F23/SUM(F$22:F$25)% -> 21.374432 | H23: 1 | I23: 11.111111 | J23: 2 | K23: 22.222222 | L23: 2 | M23: =L23/SUM(L$22:L$25)% -> 22.222222
A24: SP/GB | B24: 2632 | C24: 17.840439 | D24: 3309 | E24: 16.765466 | F24: 2600 | G24: =F24/SUM(F$22:F$25)% -> 18.768498 | H24: 2 | I24: 22.222222 | J24: 1 | K24: 11.111111 | L24: 2 | M24: =L24/SUM(L$22:L$25)% -> 22.222222
A25: SVP | B25: 4685 | C25: 31.756253 | D25: 6207 | E25: 31.448548 | F25: 3498 | G25: =F25/SUM(F$22:F$25)% -> 25.250848 | H25: 3 | I25: 33.333333 | J25: 3 | K25: 33.333333 | L25: 2 | M25: =L25/SUM(L$22:L$25)% -> 22.222222
A27: Total | B27: 76029 | D27: 94795 | F27: =SUM(F6:F26) -> 69674 | H27: =SUM(H6:H26) -> 37 | J27: =SUM(J6:J26) -> 37 | L27: =SUM(L6:L26) -> 37
A32: Listenstimmen Total | F32: 2024 manuell
A33: Partei | B33: Parteistärke | H33: Sitze | P33: Partei | Q33: Parteistärke | W33: Sitze
B34: 2016 | D34: 2020 | F34: 2024 | H34: 2016 | J34: 2020 | L34: 2024 | Q34: 2016 | S34: 2020 | U34: 2024 | W34: =Q34 -> 2016 | Y34: =S34 -> 2020 | AA34: =U34 -> 2024
B35: abs. | C35: % | D35: abs. | E35: % | F35: abs. | G35: % | H35: abs. | I35: % | J35: abs. | K35: % | L35: abs. | M35: % | Q35: abs. | R35: % | S35: abs. | T35: % | U35: abs. | V35: % | W35: abs. | X35: % | Y35: abs. | Z35: % | AA35: abs. | AB35: %
A37: Altdorf | P37: CVP | Q37: 29070 | R37: 30.666174 | S37: 21396 | T37: 30.708729 | U37: =SUMIF($A$38:$A$60,$P37,F$38:F$60) -> 27957 | V37: =U37/SUM(U$37:U$41)% -> 31.985584 | W37: 12 | X37: 32.432432 | Y37: 12 | Z37: 32.432432 | AA37: =SUMIF($A$38:$A$60,$P37,L$38:L$60) -> 11 | AB37: =AA37/SUM(AA$37:AA$41)% -> 29.72973
A38: CVP | B38: 16586 | C38: 30.68924 | D38: 11471 | E38: 28.4 | F38: 16500 | G38: =F38/SUM(F$38:F$42)% -> 32.113663 | H38: 5 | I38: 33.333333 | J38: 5 | K38: =J38/SUM(J$7:J$10)% -> 33.333333 | L38: 4 | M38: =L38/SUM(L$38:L$42)% -> 26.666667 | P38: FDP | Q38: 19065 | R38: 20.11182 | S38: 14687 | T38: 21.079599 | U38: =SUMIF($A$38:$A$60,$P38,F$38:F$60) -> 15483 | V38: =U38/SUM(U$37:U$41)% -> 17.71409 | W38: 7 | X38: 18.918919 | Y38: 7 | Z38: 18.918919 | AA38: =SUMIF($A$38:$A$60,$P38,L$38:L$60) -> 7 | AB38: =AA38/SUM(AA$37:AA$41)% -> 18.918919
A39: FDP | B39: 11434 | C39: 21.156444 | D39: 9213 | E39: 22.8 | F39: 8936 | G39: =F39/SUM(F$38:F$42)% -> 17.391981 | H39: 3 | I39: 20 | J39: 3 | K39: =J39/SUM(J$7:J$10)% -> 20 | L39: 3 | M39: =L39/SUM(L$38:L$42)% -> 20 | P39: GLP | U39: =SUMIF($A$38:$A$60,$P39,F$38:F$60) -> 8592 | V39: =U39/SUM(U$37:U$41)% -> 9.8301013 | AA39: =SUMIF($A$38:$A$60,$P39,L$38:L$60) -> 3 | AB39: =AA39/SUM(AA$37:AA$41)% -> 8.1081081
A40: GLP | F40: 6468 | G40: =F40/SUM(F$38:F$42)% -> 12.588556 | L40: 2 | M40: =L40/SUM(L$38:L$42)% -> 13.333333 | P40: SP/GB | Q40: 22578 | R40: 23.817712 | S40: 17819 | T40: 25.57482 | U40: =SUMIF($A$38:$A$60,$P40,F$38:F$60) -> 16488 | V40: =U40/SUM(U$37:U$41)% -> 18.863909 | W40: 8 | X40: 21.621622 | Y40: 9 | Z40: 24.324324 | AA40: =SUMIF($A$38:$A$60,$P40,L$38:L$60) -> 7 | AB40: =AA40/SUM(AA$37:AA$41)% -> 18.918919
A41: SP/GB | B41: 14462 | C41: 26.759182 | D41: 11908 | E41: 29.5 | F41: 10578 | G41: =F41/SUM(F$38:F$42)% -> 20.587777 | H41: 4 | I41: 26.666667 | J41: 4 | K41: =J41/SUM(J$7:J$10)% -> 26.666667 | L41: 3 | M41: =L41/SUM(L$38:L$42)% -> 20 | P41: SVP | Q41: 24082 | R41: 25.404293 | S41: 15772 | T41: 22.636852 | U41: =SUMIF($A$38:$A$60,$P41,F$38:F$60) -> 18885 | V41: =U41/SUM(U$37:U$41)% -> 21.606315 | W41: 10 | X41: 27.027027 | Y41: 9 | Z41: 24.324324 | AA41: =SUMIF($A$38:$A$60,$P41,L$38:L$60) -> 9 | AB41: =AA41/SUM(AA$37:AA$41)% -> 24.324324
A42: SVP | B42: 11563 | C42: 21.395134 | D42: 7756 | E42: 19.2 | F42: 8898 | G42: =F42/SUM(F$38:F$42)% -> 17.318023 | H42: 3 | I42: 20 | J42: 3 | K42: =J42/SUM(J$7:J$10)% -> 20 | L42: 3 | M42: =L42/SUM(L$38:L$42)% -> 20
A43: Bürglen | P43: Total | Q43: =SUM(Q37:Q42) -> 94795 | S43: =SUM(S37:S42) -> 69674 | U43: =SUM(U37:U42) -> 87405 | W43: =SUM(W37:W42) -> 37 | Y43: =SUM(Y37:Y42) -> 37 | AA43: =SUM(AA37:AA42) -> 37
A44: CVP | B44: 3567 | C44: 29.016513 | D44: 2822 | E44: 31.6 | F44: 2872 | G44: =F44/SUM(F$44:F$48)% -> 26.377663 | H44: 2 | I44: 28.571429 | J44: 2 | K44: =J44/SUM(J$12:J$15)% -> 28.571429 | L44: 2 | M44: =L44/SUM(L$44:L$48)% -> 28.571429 | P44: fertig
A45: FDP | B45: 2272 | C45: 18.482063 | D45: 1567 | E45: 17.5 | F45: 1601 | G45: =F45/SUM(F$44:F$48)% -> 14.704262 | H45: 1 | I45: 14.285714 | J45: 1 | K45: =J45/SUM(J$12:J$15)% -> 14.285714 | L45: 1 | M45: =L45/SUM(L$44:L$48)% -> 14.285714
A46: GLP | F46: 1219 | G46: =F46/SUM(F$44:F$48)% -> 11.195812 | L46: 1 | M46: =L46/SUM(L$44:L$48)% -> 14.285714 | U46: =U43-27957-16488-15483-8592-18885 -> 0
A47: SP/GB | B47: 2465 | C47: 20.052062 | D47: 1606 | E47: 18 | F47: 1395 | G47: =F47/SUM(F$44:F$48)% -> 12.81227 | H47: 1 | I47: 14.285714 | J47: 1 | K47: =J47/SUM(J$12:J$15)% -> 14.285714 | L47: 1 | M47: =L47/SUM(L$44:L$48)% -> 14.285714
...

Sheet 8.1 Panaschieren
A1: 2020 | L1: 2024 | M1: aus Formular 3b --> fertig
A2: CVP | L2: CVP
A3: Gemeinde | B3: Listen-stimmen | C3: Gewinne von | F3: Verluste an | I3: Saldo | L3: Gemeinde | M3: Listen-stimmen | N3: Gewinne von | R3: Verluste an | V3: Saldo
C4: FDP | D4: SP/GB | E4: SVP | F4: FDP | G4: SP/GB | H4: SVP | I4: abs. | J4: in % | N4: FDP | O4: GLP | P4: SP/GB | Q4: SVP | R4: FDP | S4: GLP | T4: SP/GB | U4: SVP | V4: abs. | W4: in %
A6: Altdorf | B6: ='722 Verteilung Gden'!F7 -> 11471 | C6: 819 | D6: 639 | E6: 233 | F6: =C18 -> 809 | G6: =C42 -> 580 | H6: =C55 -> 217 | I6: =C6+D6+E6-F6-G6-H6 -> 85 | J6: =I6/B6% -> 0.74099904 | L6: Altdorf | M6: ='722 Verteilung Gden'!F38 -> 16500 | N6: 564 | O6: 494 | P6: 504 | Q6: 246 | R6: =N18 -> 809 | S6: =N30 -> 442 | T6: =N42 -> 380 | U6: =N55 -> 280 | V6: =N6+O6+P6+Q6-R6-S6-T6-U6 -> -103 | W6: =V6/M6% -> -0.62424242
A7: Bürglen | B7: ='722 Verteilung Gden'!F12 -> 2822 | C7: 71 | D7: 102 | E7: 141 | F7: =C19 -> 140 | G7: =C44 -> 99 | H7: =C56 -> 111 | I7: =C7+D7+E7-F7-G7-H7 -> -36 | J7: =I7/B7% -> -1.275691 | L7: Bürglen | M7: ='722 Verteilung Gden'!F44 -> 2872 | N7: 82 | O7: 58 | P7: 58 | Q7: 144 | R7: =N19 -> 125 | S7: =N31 -> 112 | T7: =N44 -> 58 | U7: =N56 -> 85 | V7: =N7+O7+P7+Q7-R7-S7-T7-U7 -> -38 | W7: =V7/M7% -> -1.3231198
A8: Erstfeld | B8: ='722 Verteilung Gden'!F17 -> 2309 | C8: 47 | D8: 89 | E8: 113 | F8: =C20 -> 65 | G8: =C45 -> 59 | H8: =C57 -> 108 | I8: =C8+D8+E8-F8-G8-H8 -> 17 | J8: =I8/B8% -> 0.73624946 | L8: Erstfeld | M8: ='722 Verteilung Gden'!F50 -> 1878 | N8: 78 | O8: 0 | P8: 64 | Q8: 86 | R8: =N20 -> 95 | S8: =N32 -> 0 | T8: =N45 -> 94 | U8: =N57 -> 63 | V8: =N8+O8+P8+Q8-R8-S8-T8-U8 -> -24 | W8: =V8/M8% -> -1.2779553
A9: Schattdorf | B9: ='722 Verteilung Gden'!F22 -> 4794 | C9: 321 | D9: 158 | E9: 195 | F9: =C21 -> 309 | G9: =C46 -> 213 | H9: =C58 -> 123 | I9: =C9+D9+E9-F9-G9-H9 -> 29 | J9: =I9/B9% -> 0.60492282 | L9: Schattdorf | M9: ='722 Verteilung Gden'!F56 -> 6707 | N9: 313 | O9: 95 | P9: 106 | Q9: 264 | R9: =N21 -> 414 | S9: =N33 -> 57 | T9: =N46 -> 165 | U9: =N58 -> 151 | V9: =N9+O9+P9+Q9-R9-S9-T9-U9 -> -9 | W9: =V9/M9% -> -0.13418816
A11: Total | B11: =SUM(B6:B9) -> 21396 | C11: =SUM(C6:C9) -> 1258 | D11: =SUM(D6:D9) -> 988 | E11: =SUM(E6:E9) -> 682 | F11: =SUM(F6:F9) -> 1323 | G11: =SUM(G6:G9) -> 951 | H11: =SUM(H6:H9) -> 559 | I11: =C11+D11+E11-F11-G11-H11 -> 95 | J11: =I11/B11% -> 0.44400823 | L11: Total | M11: =SUM(M6:M9) -> 27957 | N11: =SUM(N6:N9) -> 1037 | O11: =SUM(O6:O9) -> 647 | P11: =SUM(P6:P9) -> 732 | Q11: =SUM(Q6:Q9) -> 740 | R11: =SUM(R6:R9) -> 1443 | S11: =SUM(S6:S9) -> 611 | T11: =SUM(T6:T9) -> 697 | U11: =SUM(U6:U9) -> 579 | V11: =N11+O11+P11+Q11-R11-S11-T11-U11 -> -174 | W11: =V11/M11% -> -0.62238438
A14: FDP | L14: FDP
A15: Gemeinde | B15: Listen-stimmen | C15: Gewinne von | F15: Verluste an | I15: Saldo | L15: Gemeinde | M15: Listen-stimmen | N15: Gewinne von | R15: Verluste an | V15: Saldo
C16: CVP | D16: SP/GB | E16: SVP | F16: CVP | G16: SP/GB | H16: SVP | I16: abs. | J16: in % | N16: CVP | O16: GLP | P16: SP/GB | Q16: SVP | R16: CVP | S16: GLP | T16: SP/GB | U16: SVP | V16: abs. | W16: in %
A18: Altdorf | B18: ='722 Verteilung Gden'!F8 -> 9213 | C18: 809 | D18: 352 | E18: 186 | F18: =C6 -> 819 | G18: =D42 -> 218 | H18: =D55 -> 238 | I18: =C18+D18+E18-F18-G18-H18 -> 72 | J18: =I18/B18% -> 0.7815044 | L18: Altdorf | M18: ='722 Verteilung Gden'!F39 -> 8936 | N18: 809 | O18: 281 | P18: 217 | Q18: 173 | R18: =N6 -> 564 | S18: =O30 -> 190 | T18: =O42 -> 66 | U18: =O55 -> 159 | V18: =N18+O18+P18+Q18-R18-S18-T18-U18 -> 501 | W18: =V18/M18% -> 5.6065354
A19: Bürglen | B19: ='722 Verteilung Gden'!F13 -> 1567 | C19: 140 | D19: 63 | E19: 71 | F19: =C7 -> 71 | G19: =D44 -> 25 | H19: =D56 -> 23 | I19: =C19+D19+E19-F19-G19-H19 -> 155 | J19: =I19/B19% -> 9.8915124 | L19: Bürglen | M19: ='722 Verteilung Gden'!F45 -> 1601 | N19: 125 | O19: 47 | P19: 24 | Q19: 101 | R19: =N7 -> 82 | S19: =O31 -> 36 | T19: =O44 -> 13 | U19: =O56 -> 37 | V19: =N19+O19+P19+Q19-R19-S19-T19-U19 -> 129 | W19: =V19/M19% -> 8.0574641
A20: Erstfeld | B20: ='722 Verteilung Gden'!F18 -> 946 | C20: 65 | D20: 32 | E20: 62 | F20: =C8 -> 47 | G20: =D45 -> 5 | H20: =D57 -> 34 | I20: =C20+D20+E20-F20-G20-H20 -> 73 | J20: =I20/B20% -> 7.7167019 | L20: Erstfeld | M20: ='722 Verteilung Gden'!F51 -> 1554 | N20: 95 | O20: 0 | P20: 47 | Q20: 115 | R20: =N8 -> 78 | S20: =O32 -> 0 | T20: =O45 -> 41 | U20: =O57 -> 57 | V20: =N20+O20+P20+Q20-R20-S20-T20-U20 -> 81 | W20: =V20/M20% -> 5.2123552
A21: Schattdorf | B21: ='722 Verteilung Gden'!F23 -> 2961 | C21: 309 | D21: 60 | E21: 129 | F21: =C9 -> 321 | G21: =D46 -> 67 | H21: =D58 -> 73 | I21: =C21+D21+E21-F21-G21-H21 -> 37 | J21: =I21/B21% -> 1.2495778 | L21: Schattdorf | M21: ='722 Verteilung Gden'!F57 -> 3392 | N21: 414 | O21: 54 | P21: 24 | Q21: 158 | R21: =N9 -> 313 | S21: =O33 -> 42 | T21: =O46 -> 43 | U21: =O58 -> 78 | V21: =N21+O21+P21+Q21-R21-S21-T21-U21 -> 174 | W21: =V21/M21% -> 5.129717
A23: Total | B23: =SUM(B18:B21) -> 14687 | C23: =SUM(C18:C21) -> 1323 | D23: =SUM(D18:D21) -> 507 | E23: =SUM(E18:E21) -> 448 | F23: =SUM(F18:F21) -> 1258 | G23: =SUM(G18:G21) -> 315 | H23: =SUM(H18:H21) -> 368 | I23: =C23+D23+E23-F23-G23-H23 -> 337 | J23: =I23/B23% -> 2.2945462 | L23: Total | M23: =SUM(M18:M21) -> 15483 | N23: =SUM(N18:N21) -> 1443 | O23: =SUM(O18:O21) -> 382 | P23: =SUM(P18:P21) -> 312 | Q23: =SUM(Q18:Q21) -> 547 | R23: =SUM(R18:R21) -> 1037 | S23: =SUM(S18:S21) -> 268 | T23: =SUM(T18:T21) -> 163 | U23: =SUM(U18:U21) -> 331 | V23: =N23+O23+P23+Q23-R23-S23-T23-U23 -> 885 | W23: =V23/M23% -> 5.7159465
L26: GLP
L27: Gemeinde | M27: Listen-stimmen | N27: Gewinne von | R27: Verluste an | V27: Saldo
N28: CVP | O28: FDP | P28: SP/GB | Q28: SVP | R28: CVP | S28: FDP | T28: SP/GB | U28: SVP | V28: abs. | W28: in %
L30: Altdorf | M30: ='722 Verteilung Gden'!F40 -> 6468 | N30: 442 | O30: 190 | P30: 402 | Q30: 45 | R30: =O6 -> 494 | S30: =O18 -> 281 | T30: =P42 -> 334 | U30: =P55 -> 45 | V30: =N30+O30+P30+Q30-R30-S30-T30-U30 -> -75 | W30: =V30/M30% -> -1.1595547
L31: Bürglen | M31: ='722 Verteilung Gden'!F46 -> 1219 | N31: 112 | O31: 36 | P31: 87 | Q31: 17 | R31: =O7 -> 58 | S31: =O19 -> 47 | T31: =P44 -> 49 | U31: =P56 -> 18 | V31: =N31+O31+P31+Q31-R31-S31-T31-U31 -> 80 | W31: =V31/M31% -> 6.5627564
L32: Erstfeld | M32: ='722 Verteilung Gden'!F52 -> 0 | N32: 0 | O32: 0 | P32: 0 | Q32: 0 | R32: =O8 -> 0 | S32: =O20 -> 0 | T32: =P45 -> 0 | U32: =P57 -> 0 | V32: =N32+O32+P32+Q32-R32-S32-T32-U32 -> 0 | W32: 0
L33: Schattdorf | M33: ='722 Verteilung Gden'!F58 -> 905 | N33: 57 | O33: 42 | P33: 45 | Q33: 11 | R33: =O9 -> 95 | S33: =O21 -> 54 | T33: =P46 -> 80 | U33: =P58 -> 11 | V33: =N33+O33+P33+Q33-R33-S33-T33-U33 -> -85 | W33: =V33/M33% -> -9.3922652
L35: Total | M35: =SUM(M30:M33) -> 8592 | N35: =SUM(N30:N33) -> 611 | O35: =SUM(O30:O33) -> 268 | P35: =SUM(P30:P33) -> 534 | Q35: =SUM(Q30:Q33) -> 73 | R35: =SUM(R30:R33) -> 647 | S35: =SUM(S30:S33) -> 382 | T35: =SUM(T30:T33) -> 463 | U35: =SUM(U30:U33) -> 74 | V35: =N35+O35+P35+Q35-R35-S35-T35-U35 -> -80 | W35: =V35/M35% -> -0.9310987
A38: SP/GB | L38: SP/GB
A39: Gemeinde | B39: Listen-stimmen | C39: Gewinne von | F39: Verluste an | I39: Saldo | L39: Gemeinde | M39: Listen-stimmen | N39: Gewinne von | R39: Verluste an | V39: Saldo
C40: CVP | D40: FDP | E40: SVP | F40: CVP | G40: FDP | H40: SVP | I40: abs. | J40: in % | N40: CVP | O40: FDP | P40: GLP | Q40: SVP | R40: CVP | S40: FDP | T40: GLP | U40: SVP | V40: abs. | W40: in %
A42: Altdorf | B42: ='722 Verteilung Gden'!F9 -> 11908 | C42: 580 | D42: 218 | E42: 52 | F42: =D6 -> 639 | G42: =D18 -> 352 | H42: =E55 -> 35 | I42: =C42+D42+E42-F42-G42-H42 -> -176 | J42: =I42/B42% -> -1.477998 | L42: Altdorf | M42: ='722 Verteilung Gden'!F41 -> 10578 | N42: 380 | O42: 66 | P42: 334 | Q42: 19 | R42: =P6 -> 504 | S42: =P18 -> 217 | T42: =P30 -> 402 | U42: =Q55 -> 24 | V42: =N42+O42+P42+Q42-R42-S42-T42-U42 -> -348 | W42: =V42/M42% -> -3.2898469
V43: =N43+O43+P43+Q43-R43-S43-T43-U43 -> 0
A44: Bürglen | B44: ='722 Verteilung Gden'!F14 -> 1606 | C44: 99 | D44: 25 | E44: 7 | F44: =D7 -> 102 | G44: =D19 -> 63 | H44: =E56 -> 4 | I44: =C44+D44+E44-F44-G44-H44 -> -38 | J44: =I44/B44% -> -2.366127 | L44: Bürglen | M44: ='722 Verteilung Gden'!F47 -> 1395 | N44: 58 | O44: 13 | P44: 49 | Q44: 3 | R44: =P7 -> 58 | S44: =P19 -> 24 | T44: =P31 -> 87 | U44: =Q56 -> 7 | V44: =N44+O44+P44+Q44-R44-S44-T44-U44 -> -53 | W44: =V44/M44% -> -3.7992832
A45: Erstfeld | B45: ='722 Verteilung Gden'!F19 -> 1705 | C45: 59 | D45: 5 | E45: 13 | F45: =D8 -> 89 | G45: =D20 -> 32 | H45: =E57 -> 20 | I45: =C45+D45+E45-F45-G45-H45 -> -64 | J45: =I45/B45% -> -3.7536657 | L45: Erstfeld | M45: ='722 Verteilung Gden'!F53 -> 2157 | N45: 94 | O45: 41 | P45: 0 | Q45: 54 | R45: =P8 -> 64 | S45: =P20 -> 47 | T45: =P32 -> 0 | U45: =Q57 -> 8 | V45: =N45+O45+P45+Q45-R45-S45-T45-U45 -> 70 | W45: =V45/M45% -> 3.245248
A46: Schattdorf | B46: ='722 Verteilung Gden'!F24 -> 2600 | C46: 213 | D46: 67 | E46: 21 | F46: =D9 -> 158 | G46: =D21 -> 60 | H46: =E58 -> 6 | I46: =C46+D46+E46-F46-G46-H46 -> 77 | J46: =I46/B46% -> 2.9615385 | L46: Schattdorf | M46: ='722 Verteilung Gden'!F59 -> 2358 | N46: 165 | O46: 43 | P46: 80 | Q46: 27 | R46: =P9 -> 106 | S46: =P21 -> 24 | T46: =P33 -> 45 | U46: =Q58 -> 16 | V46: =N46+O46+P46+Q46-R46-S46-T46-U46 -> 124 | W46: =V46/M46% -> 5.2586938
A48: Total | B48: =SUM(B42:B46) -> 17819 | C48: =SUM(C42:C46) -> 951 | D48: =SUM(D42:D46) -> 315 | E48: =SUM(E42:E46) -> 93 | F48: =SUM(F42:F46) -> 988 | G48: =SUM(G42:G46) -> 507 | H48: =SUM(H42:H46) -> 65 | I48: =C48+D48+E48-F48-G48-H48 -> -201 | J48: =I48/B48% -> -1.1280094 | L48: Total | M48: =SUM(M42:M46) -> 16488 | N48: =SUM(N42:N46) -> 697 | O48: =SUM(O42:O46) -> 163 | P48: =SUM(P42:P46) -> 463 | Q48: =SUM(Q42:Q46) -> 103 | R48: =SUM(R42:R46) -> 732 | S48: =SUM(S42:S46) -> 312 | T48: =SUM(T42:T46) -> 534 | U48: =SUM(U42:U46) -> 55 | V48: =N48+O48+P48+Q48-R48-S48-T48-U48 -> -207 | W48: =V48/M48% -> -1.2554585
A51: SVP | L51: SVP
A52: Gemeinde | B52: Listen-stimmen | C52: Gewinne von | F52: Verluste an | I52: Saldo | L52: Gemeinde | M52: Listen-stimmen | N52: Gewinne von | R52: Verluste an | V52: Saldo
C53: CVP | D53: FDP | E53: SP/GB | F53: CVP | G53: FDP | H53: SP/GB | I53: abs. | J53: in % | N53: CVP | O53: FDP | P53: GLP | Q53: SP/GB | R53: CVP | S53: FDP | T53: GLP | U53: SP/GB | V53: abs. | W53: in %
A55: Altdorf | B55: ='722 Verteilung Gden'!F10 -> 7756 | C55: 217 | D55: 238 | E55: 35 | F55: =E6 -> 233 | G55: =E18 -> 186 | H55: =E42 -> 52 | I55: =C55+D55+E55-F55-G55-H55 -> 19 | J55: =I55/B55% -> 0.24497163 | L55: Altdorf | M55: ='722 Verteilung Gden'!F42 -> 8898 | N55: 280 | O55: 159 | P55: 45 | Q55: 24 | R55: =Q6 -> 246 | S55: =Q18 -> 173 | T55: =Q30 -> 45 | U55: =Q42 -> 19 | V55: =N55+O55+P55+Q55-R55-S55-T55-U55 -> 25 | W55: =V55/M55% -> 0.28096201
A56: Bürglen | B56: ='722 Verteilung Gden'!F15 -> 2945 | C56: 111 | D56: 23 | E56: 4 | F56: =E7 -> 141 | G56: =E19 -> 71 | H56: =E44 -> 7 | I56: =C56+D56+E56-F56-G56-H56 -> -81 | J56: =I56/B56% -> -2.7504244 | L56: Bürglen | M56: ='722 Verteilung Gden'!F48 -> 3801 | N56: 85 | O56: 37 | P56: 18 | Q56: 7 | R56: =Q7 -> 144 | S56: =Q19 -> 101 | T56: =Q31 -> 17 | U56: =Q44 -> 3 | V56: =N56+O56+P56+Q56-R56-S56-T56-U56 -> -118 | W56: =V56/M56% -> -3.1044462
A57: Erstfeld | B57: ='722 Verteilung Gden'!F20 -> 1573 | C57: 108 | D57: 34 | E57: 20 | F57: =E8 -> 113 | G57: =E20 -> 62 | H57: =E45 -> 13 | I57: =C57+D57+E57-F57-G57-H57 -> -26 | J57: =I57/B57% -> -1.6528926 | L57: Erstfeld | M57: ='722 Verteilung Gden'!F54 -> 2032 | N57: 63 | O57: 57 | P57: 0 | Q57: 8 | R57: =Q8 -> 86 | S57: =Q20 -> 115 | T57: =Q32 -> 0 | U57: =Q45 -> 54 | V57: =N57+O57+P57+Q57-R57-S57-T57-U57 -> -127 | W57: =V57/M57% -> -6.25
...

Sheet 8.2 Kumulieren
A1: Zahlen "Stimmen" kommen aus Formular 5b, Rest kommt aus dem Formular 3c (pro Gemeinde), % = Anteil kumulierte Stimmen auf anderen Listen an der Gesamtstimmenzahl (Formel hinterlegt)
A3: Altdorf, CVP | B3: Name | C3: Stimmen | D3: Kumulierte Kandidatenstimmen auf Listen der | K3: FDP | L3: Name | M3: Stimmen | N3: Kumulierte Kandidatenstimmen auf Listen der | U3: GLP | V3: Name | W3: Stimmen | X3: Kumulierte Kandidatenstimmen auf Listen der | AE3: SP/GB | AF3: Name | AG3: Stimmen | AH3: Kumulierte Kandidatenstimmen auf Listen der | AO3: SVP | AP3: Name | AQ3: Stimmen | AR3: Kumulierte Kandidatenstimmen auf Listen der
D4: FDP | E4: GLP | F4: SP/GB | G4: SVP | H4: FL | I4: Total | J4: in % | N4: CVP | O4: GLP | P4: SP/GB | Q4: SVP | R4: FL | S4: Total | T4: in % | X4: CVP | Y4: FDP | Z4: SP/GB | AA4: SVP | AB4: FL | AC4: Total | AD4: in % | AH4: CVP | AI4: FDP | AJ4: GLP | AK4: SVP | AL4: FL | AM4: Total | AN4: in % | AR4: CVP | AS4: FDP | AT4: GLP | AU4: SP/GB | AV4: FL | AW4: Total | AX4: in %
B6: Huber Céline | C6: 2424 | D6: 90 | E6: 54 | F6: 62 | G6: 38 | H6: 242 | I6: =SUM(D6:H6) -> 486 | J6: =I6/C6% -> 20.049505 | L6: Tarelli Dori | M6: 1558 | N6: 92 | O6: 42 | P6: 46 | Q6: 14 | R6: 150 | S6: =SUM(N6:R6) -> 344 | T6: =S6/M6% -> 22.079589 | V6: Baumann Noel | W6: 1140 | X6: 58 | Y6: 34 | Z6: 76 | AA6: 10 | AB6: 140 | AC6: =SUM(X6:AB6) -> 318 | AD6: =AC6/W6% -> 27.894737 | AF6: Schmidt Valentin | AG6: 1452 | AH6: 28 | AI6: 0 | AJ6: 30 | AK6: 0 | AL6: 82 | AM6: =SUM(AH6:AL6) -> 140 | AN6: =AM6/AG6% -> 9.6418733 | AP6: von Mentlen Michael | AQ6: 1232 | AR6: 22 | AS6: 16 | AT6: 8 | AU6: 2 | AV6: 72 | AW6: =SUM(AR6:AV6) -> 120 | AX6: =AW6/AQ6% -> 9.7402597
B7: Arnold Barengo Michael | C7: 1502 | D7: 22 | E7: 22 | F7: 36 | G7: 8 | H7: 112 | I7: =SUM(D7:H7) -> 200 | J7: =I7/C7% -> 13.315579 | L7: Muheim Quick Petra | M7: 1515 | N7: 132 | O7: 48 | P7: 28 | Q7: 26 | R7: 152 | S7: =SUM(N7:R7) -> 386 | T7: =S7/M7% -> 25.478548 | V7: Wild Loa | W7: 810 | X7: 12 | Y7: 12 | Z7: 40 | AA7: 0 | AB7: 62 | AC7: =SUM(X7:AB7) -> 126 | AD7: =AC7/W7% -> 15.555556 | AF7: Imhof Jonas | AG7: 1431 | AH7: 26 | AI7: 8 | AJ7: 36 | AK7: 2 | AL7: 66 | AM7: =SUM(AH7:AL7) -> 138 | AN7: =AM7/AG7% -> 9.6436059 | AP7: Brunner Claudia | AQ7: 1218 | AR7: 20 | AS7: 30 | AT7: 4 | AU7: 0 | AV7: 46 | AW7: =SUM(AR7:AV7) -> 100 | AX7: =AW7/AQ7% -> 8.2101806
B8: Keusch Rafael | C8: 1400 | D8: 26 | E8: 20 | F8: 32 | G8: 20 | H8: 114 | I8: =SUM(D8:H8) -> 212 | J8: =I8/C8% -> 15.142857 | L8: Schillig Ivo | M8: 1280 | N8: 38 | O8: 6 | P8: 10 | Q8: 22 | R8: 86 | S8: =SUM(N8:R8) -> 162 | T8: =S8/M8% -> 12.65625 | V8: Zgraggen Fabian | W8: 660 | X8: 10 | Y8: 4 | Z8: 12 | AA8: 0 | AB8: 18 | AC8: =SUM(X8:AB8) -> 44 | AD8: =AC8/W8% -> 6.6666667 | AF8: Arnold Nino | AG8: 1393 | AH8: 26 | AI8: 8 | AJ8: 38 | AK8: 6 | AL8: 86 | AM8: =SUM(AH8:AL8) -> 164 | AN8: =AM8/AG8% -> 11.773151 | AP8: Affentranger Fabio | AQ8: 1166 | AR8: 12 | AS8: 8 | AT8: 4 | AU8: 6 | AV8: 32 | AW8: =SUM(AR8:AV8) -> 62 | AX8: =AW8/AQ8% -> 5.3173242
B9: Gisler Kurt | C9: 1398 | D9: 36 | E9: 12 | F9: 24 | G9: 14 | H9: 84 | I9: =SUM(D9:H9) -> 170 | J9: =I9/C9% -> 12.160229 | L9: Heinzer Andrea | M9: 968 | N9: 10 | O9: 14 | P9: 16 | Q9: 4 | R9: 58 | S9: =SUM(N9:R9) -> 102 | T9: =S9/M9% -> 10.53719 | V9: Britschgi Urs | W9: 526 | X9: 24 | Y9: 12 | Z9: 14 | AA9: 14 | AB9: 42 | AC9: =SUM(X9:AB9) -> 106 | AD9: =AC9/W9% -> 20.152091 | AF9: Walker Stephanie | AG9: 1332 | AH9: 22 | AI9: 2 | AJ9: 18 | AK9: 0 | AL9: 50 | AM9: =SUM(AH9:AL9) -> 92 | AN9: =AM9/AG9% -> 6.9069069 | AP9: Arnold Stefan | AQ9: 1050 | AR9: 16 | AS9: 6 | AT9: 2 | AU9: 4 | AV9: 32 | AW9: =SUM(AR9:AV9) -> 60 | AX9: =AW9/AQ9% -> 5.7142857
